(7926, 4)
hatespeech                    0
counterspeech                 0
predicted_counterspeech    1400
uuid                          0
dtype: int64
Starting Run
Getting Predictions: 0it [00:00, ?it/s]Getting Predictions: 0it [00:00, ?it/s]
Traceback (most recent call last):
  File "/home/amey/miniconda3/envs/socionet/lib/python3.9/site-packages/urllib3/connectionpool.py", line 712, in urlopen
    self._prepare_proxy(conn)
  File "/home/amey/miniconda3/envs/socionet/lib/python3.9/site-packages/urllib3/connectionpool.py", line 1012, in _prepare_proxy
    conn.connect()
  File "/home/amey/miniconda3/envs/socionet/lib/python3.9/site-packages/urllib3/connection.py", line 374, in connect
    self._tunnel()
  File "/home/amey/miniconda3/envs/socionet/lib/python3.9/http/client.py", line 930, in _tunnel
    raise OSError(f"Tunnel connection failed: {code} {message.strip()}")
OSError: Tunnel connection failed: 302 Moved Temporarily

During handling of the above exception, another exception occurred:

Traceback (most recent call last):
  File "/home/amey/miniconda3/envs/socionet/lib/python3.9/site-packages/requests/adapters.py", line 486, in send
    resp = conn.urlopen(
  File "/home/amey/miniconda3/envs/socionet/lib/python3.9/site-packages/urllib3/connectionpool.py", line 827, in urlopen
    return self.urlopen(
  File "/home/amey/miniconda3/envs/socionet/lib/python3.9/site-packages/urllib3/connectionpool.py", line 827, in urlopen
    return self.urlopen(
  File "/home/amey/miniconda3/envs/socionet/lib/python3.9/site-packages/urllib3/connectionpool.py", line 799, in urlopen
    retries = retries.increment(
  File "/home/amey/miniconda3/envs/socionet/lib/python3.9/site-packages/urllib3/util/retry.py", line 592, in increment
    raise MaxRetryError(_pool, url, error or ResponseError(cause))
urllib3.exceptions.MaxRetryError: HTTPSConnectionPool(host='api.together.xyz', port=443): Max retries exceeded with url: /v1/chat/completions (Caused by ProxyError('Cannot connect to proxy.', OSError('Tunnel connection failed: 302 Moved Temporarily')))

During handling of the above exception, another exception occurred:

Traceback (most recent call last):
  File "/home/amey/miniconda3/envs/socionet/lib/python3.9/site-packages/together/abstract/api_requestor.py", line 489, in request_raw
    result = _thread_context.session.request(
  File "/home/amey/miniconda3/envs/socionet/lib/python3.9/site-packages/requests/sessions.py", line 589, in request
    resp = self.send(prep, **send_kwargs)
  File "/home/amey/miniconda3/envs/socionet/lib/python3.9/site-packages/requests/sessions.py", line 703, in send
    r = adapter.send(request, **kwargs)
  File "/home/amey/miniconda3/envs/socionet/lib/python3.9/site-packages/requests/adapters.py", line 513, in send
    raise ProxyError(e, request=request)
requests.exceptions.ProxyError: HTTPSConnectionPool(host='api.together.xyz', port=443): Max retries exceeded with url: /v1/chat/completions (Caused by ProxyError('Cannot connect to proxy.', OSError('Tunnel connection failed: 302 Moved Temporarily')))

During handling of the above exception, another exception occurred:

Traceback (most recent call last):
  File "/home/amey/depository/cs-eval/togetherai_inference_mistral_zs.py", line 68, in <module>
    content = predict(prompt, system_description)
  File "/home/amey/depository/cs-eval/togetherai_inference_mistral_zs.py", line 19, in predict
    response = client.chat.completions.create(
  File "/home/amey/miniconda3/envs/socionet/lib/python3.9/site-packages/together/resources/chat/completions.py", line 136, in create
    response, _, _ = requestor.request(
  File "/home/amey/miniconda3/envs/socionet/lib/python3.9/site-packages/together/abstract/api_requestor.py", line 242, in request
    result = self.request_raw(
  File "/home/amey/miniconda3/envs/socionet/lib/python3.9/site-packages/together/abstract/api_requestor.py", line 520, in request_raw
    response_headers=dict(result.headers),
UnboundLocalError: local variable 'result' referenced before assignment
